## lecture 16, _06-02-23_

---

## Идеология обработки ошибок

Любая обработка ошибок — это часть алгоритма, контракта и инвариантов программы! Нет никакого способа добавить
обработку ошибок в общем случае, все инструменты языка (те же исключения) — это лишь инструменты. Если обработка
ошибок важна, её тоже надо продумывать и тестировать. Нельзя просто «сообщить об ошибке в момент возникновения и
обработать, где удобно»; это так же неточно, как «решить задачу циклами и if-ами».

### Ошибки программирования

Любое UB, нарушение инварианта (двоичный поиск, состояние класса), нарушения контракта.

```c++
void foo(const char *s) {
    printf("%s\n", s);  // Некорректный s.
}
```

Лучше выявлять на стадии тестирования.

Обычно видны не сразу, а через какое-то время. Можно пробовать проверять и детектировать (например, `vector::at`
вместо `vector::operator[]`), но не задетектирует всё (потому что баги) и неясно, что делать после обнаружения (мало в
чём можно быть уверенным).

Если случилось, то никаких гарантий, all bets are off. Баг в программе точно есть, причём неизвестный, могло упасть где
угодно.

На самом деле какие-то гарантии могут быть. John Lakos называет нарушения контракта _soft undefined behavior_ (мягкое
неопределённое поведение): всё ещё можно логически вывести поведение программы. Но оно легко приводит к _hard undefined_
_behavior_ (жёсткое неопределённое поведение): тут уже вообще ничего сделать нельзя.

Принцип кувалды: https://thephd.dev/c-undefined-behavior-and-the-sledgehammer-guideline

### Ошибки окружения/предсказуемые ошибки

Некорректный ввод пользователя, файл не найден, оборвалось сетевое соединение...

- Могут произойти независимо от программы.

- Можно предсказать при написании кода.

- Лучше обрабатывать.

- Например, клиент Telegram должен быстро работать, даже если сервер внезапно отвалился.
  Переподключиться? Держать ещё одно соединение в запасе? Надо думать.

- Не хватило прав доступа — может, наоборот, не сообщать пользователю, зато сообщить администратору.
  Бывают пограничные ситуации в разных контекстах.

**Надо думать в каждом отдельном случае.**

На хороших контестах гарантируется, что ввод корректен. В реальном мире, например, в сетевых приложениях это совсем не
так: например, нас могут хотеть взломать.

- А что если кончился стэк/память/место на диске?
    - Место на диске: можно забить, можно почистить свой собственный кэш. Это чаще не обрабатывают почему-то.
    - Память: а если при обработке потребуется ещё память?
    - Не удалась запись в файл: могут быть разные требования к чат-клиенту (который может всё скачать с сервера) и
      самому серверу (которому надо как-то восстанавливаться и централизованно сообщать "жёсткий диск сломался").
- Нарушен инвариант структуры — проблема. А вот если мы её перед этим считывали по сети, то, может, это попытка взлома и
  надо залогировать и пропустить запрос. Мораль: отделяем внешний ввод от внутренних данных программы.

Про каждую ошибку в программе _надо думать_:

1) Что случится, когда произойдёт (именно «когда», а не «если»)?
2) Можно ли с ней сделать что-то разумное с точки зрения _пользователя_?
3) Если да, то как эта обработка ошибки встраивается в алгоритм и архитектуру?

### Обработка ошибок

Почти всегда можно залогировать ошибку для разработчика.

1) **Уронить процесс целиком.** Самое безопасное при ошибках программирования. Хотя тоже может нарушить инварианты (
   например, файл не до конца записали). Можно ещё перед этим позвонить домой и отправить багрепорт. А потом немедленно
   упасть, даже если кажется, что всё хорошо.
2) **Уронить кусок процесса.** Только если не ошибка программирования (хотя в Java/Python с изоляцией получше).
   Например, мы
   сервер и порвалось соединение с клиентом.
3) **Как-то обработать**, например, попробовать другой адрес для подключения к серверу.
4) **Сообщить пользователю и попросить что-нибудь сделать**: «файл не найден, выберите другой».
    - Важно понимать, что пользователь далеко не всегда что-то может сделать. О каких ошибках и как сообщать
      пользователю — отдельный вопрос дизайна user experience.
    - Проще и надёжнее всего уронить программу целиком.

Важно запомнить, что нет серебряной пули для обработки ошибок: это такая же часть спецификации программы, над которой
надо хорошо думать заранее и отдельно реализовывать.

### Подавление ошибок

Популярная раньше идея _wide contracts_ – для каждого возможного входа иметь какую-то обработку и логический домысел.

Например, возвращение -1 для поиска максимума в векторе, если он пуст.

```c++
int max(const std::vector<int> &v) {
    if (v.empty()) return -1;
    .....
}
```

Чем плохо:

1) Если что-то пошло не так (вектор пуст), программа продолжает выполнение с каким-то значением. Может быть hard
   undefined behavior дальше.
2) Ошибки дальше может и не случиться => сложнее найти баг.

Чем хорошо: _иллюзия_, что всё хорошо.

Даже если включить в контракт, то пользователи его не прочитают и будут не ожидать.

Как обычно делают:

```c++
int max(const std::vector<int> &v) {
    assert(!v.empty());
    _ASSERT(!v.empty());  // think-cell
    BSLS_ASSERT(!v.empty());  // Bloomberg
    .....
}
```

## Механизмы обработки ошибок

### Флаги и `std::iostate`

У объекта можно ставить какой-нибудь флаг, описывающий его состояние, которое можно регулярно проверять.

Пример: чтение из файла с помощью класса `ifstream`. Если файл не открылся (что нужно проверить самостоятельно
ручками), то можно что-то сделать (в библиотеке не прописано, что именно, просто устанавливается `f.is_open() = false`).
Ошибки
записываются в `f.rdstate()` (хранит не последнюю ошибку, а состояние файла в целом) :

1) `std::ios_base::badbit` – невосстановимая ошибка, например, жесткий диск отвалился.
2) `std::ios_base::failbit` – восстановимая ошибка, например, формат нарушился и считали число вместо строки.
3) `std::ios_base::eofbit` – верно ли, что наткнулись на `EOF`.

Если у файла установлен хотя бы один такой бит, то он считается некорректным (`!f` проверяет, установлен ли хотя
какой-то бит).

Про состояние файла: https://en.cppreference.com/w/cpp/io/ios_base/iostate.

```c++
#include <fstream>

void check_file(const std::string &filename) {
    std::ifstream f(filename);
    std::cout << "Reading from " << filename << "\n";
    // Easy to forget to check.
    std::cout << "    is_open: " << f.is_open() << "\n";
    for (;;) {
        в
        // State, not result of operation
        std::cout << "    status: " << f.rdstate() << "; "
                  << std::ios_base::badbit << " "  // irrecoverable error
                  << std::ios_base::failbit << " "  // format/extract error
                  << std::ios_base::eofbit << "\n";  // EOF reached
        if (!f) {
            break;
        }
        int x = -239;
        // Careful handling is actually required
        f >> x;
        std::cout << "    x = " << x;
    }
}
```

### Глобальные переменные с ошибкой

После открытия файла в `errno` лежит код ошибки (внимательно, что код именно _последней_ ошибки, если открыть другой
файл, то он поменяется).

```c++
#include <cerrno>

void check_file(const std::string &filename) {
    FILE *f = std::fopen(filename.c_str(), "r");
    std::cout << "Reading from " << filename << "\n";
    std::cout << "    f: " << f << ", errno: " << errno << " " << std::strerror(errno) << "\n";  // POSIX (not C/C++) requires that errno macro is set.
    // Problem: have to check immediately after each function. Does not propagate up.
    if (f == nullptr) {
        return;
    }
    for (;;) {
        int x = -239;
        int read = std::fscanf(f, "%d", &x);  // Still easy to forget to check.
        std::cout << "    x = " << x << ", read = " << read << ", errno = " << errno << " " << std::strerror(errno) << "\n";
        if (read != 1) {
            break;
        }
    }
    std::fclose(f);
}

int main() {
    check_file("numbers-01-simple.in");
    check_file("numbers-02-immediate-eof.in");
    check_file("does-not-exist.in");
}
```

Еще пример: С-шная библиотека `<sqlite3.h>`. Функция `sqlite3_open` принимает ссылку на базу данных и возвращает `int`,
если удалось/не удалось открыть. Можно потом сравнивать с глобальными перменными, например, `SQLITE_OK`
или `SQLITE_CANTOPEN`.

```c++
#include <sqlite3.h>
#include <iostream>

// int sqlite3_open(
//   const char *filename,   /* Database filename (UTF-8) */
//   sqlite3 **ppDb          /* OUT: SQLite db handle */
// );

int main() {
    sqlite3 *db;
    if (int err = sqlite3_open("does-not-exist/some-db.sqlite3", &db); err != SQLITE_OK) {  // Still easy to forget to check, but syntax is ugly.
        std::cout << "err = " << err << " " << sqlite3_errstr(err) << "\n";
        if (err == SQLITE_CANTOPEN) {
            std::cout << "Unable to open DB file\n";
        }
        return 1;
    }
    sqlite3_close(db);
    return 0;
}
```

### Пример из языка rust

Функция `File::open` возвращает или файл, или ошибку, а дальше можно будет это проверить (популярно в функциональном
программировании).

```c++
// https://doc.rust-lang.org/book/ch09-02-recoverable-errors-with-result.html
use std::fs::File;
use std::io::Read;

fn main() {
let mut f = match File::open("hello.txt") {  // We have to check.
Ok(file) => file,
Err(error) => {
println!("Problem opening the file: {:?}", error);
return
},
};
let mut s = String::new();
match f.read_to_string(&mut s) {
Ok(_) => println!("File read: {:?}", s),
Err(e) => {
println!("Problem reading the file: {:?}", e);
return
}
}
}
```

Даже добавили оператор `?`, заменяющий конструкцию `if failure, return Err()`. То есть если функция может выбросить
ошибку, то она пробрасывается
на уровень нашей функции. По сути те же коды возврата, но проверка сводится к одному оператору `?`.

```c++
// https://doc.rust-lang.org/book/ch09-02-recoverable-errors-with-result.html
use std::fs::File;
use std::io::Error;
use std::io::Read;

fn main() -> Result<(), Error> {
let mut f = File::open("hello.txt")?;  // '?' is a shortcut for "if failure, return Err()".
let mut s = String::new();
f.read_to_string(&mut s)?;
println!("File read: {:?}", s);
Ok(())
}
```

### Не обрабатывать ошибки :)

...просто assert понатыкать можно.

```c++
std::vector<int> read_vector(const std::string &filename) {
    std::ifstream f(filename);
    assert(f);  // Why no handling?
    int n;
    f >> n;
    assert(f);
    std::vector<int> vec(n);
    for (int &v : vec) {
        f >> v;
        assert(f);
    }
    return vec;
}
```

### Обрабатывать на месте

Сразу при возникновении обрабатывать возникшую ошибку. С одной стороны, эта концепция позволяет достаточно точно
обработать ошибку, а с другой – иногда она роняет программу.

```c++
std::vector<int> read_vector(const std::string &filename) {
    std::ifstream f(filename);
    if (!f) {
        std::cerr << "Unable to open file\n";
        std::exit(1);
    }

    int n;
    if (!(f >> n)) {
        std::cerr << "Unable to read length of a vector\n";
        std::exit(1);
    }

    std::vector<int> vec(n);
    for (int &v : vec) {
        if (!(f >> v)) {
            std::cerr << "Unable to read number\n";
            std::exit(1);
        }
    }
    return vec;
}
```

### Пробрасывание ошибки наверх

Самая популярная концепция. Функция `read_vector` возвращает код ошибки, что пошло не так. Да, функция стала длинее раза
в 3, но безопаснее,
можно будет обработать возникшие ошибки.

Заметим, что считанные вектор не сразу записыается в `result`. То есть при возникновении ошибки он не поменяется и туда
не запишется что-то частичное.

```c++
enum class read_vector_error { OK, CANNOT_OPEN, CANNOT_READ_LENGTH, CANNOT_READ_NUMBER };

/*[[nodiscard]]*/ read_vector_error read_vector(const std::string &filename, std::vector<int> &result) {
    std::ifstream f(filename);
    if (!f) {
        return read_vector_error::CANNOT_OPEN;
    }
    
    int n;
    if (!(f >> n)) {
        return read_vector_error::CANNOT_READ_LENGTH;
    }
    
    std::vector<int> vec(n);
    for (int &v : vec) {
        if (!(f >> v)) {
            return read_vector_error::CANNOT_READ_NUMBER;
        }
    }
    result = std::move(vec);
    return read_vector_error::OK;
}
```

## Исключения

Исключения создавались для исключительных ситуаций. А дальше – дискуссия лет на 40, какая ситуация является
исключительной :)

### Базовое

Если блок `try` успешно отработает, то `catch` опустится. Если возникает ошибка типа `invalid_vector_format`, то зайдем
в блок `catch`, там можно уже что-то с ней сделать, а вот дальше она не полетит.

```c++
try {
    solve();  // if exception is thrown, it's propagated
} catch (const invalid_vector_format &err) {  // looking for the first catch
    std::cout << "Invalid vector format\n";
    // Print good error message is hard:
    // 1. How exactly the format is invalid? We could add it to the exception.
    // 2. We don't have much context here: what exactly failed? A or B?
    // 3. We don't have that context in read_vector() either.
    // Consequence: this is probably not a great error handling.
    //              Not because of exceptions per se, but because we did not think _in advance_.
}
```

Если во время считывания что-то пошло не так, то вы `throw` ошибку. `throw` ожидает какое-нибудь значение любого типа.
Чаще всего пишут какие-нибудь конструкторы.

Причем при выбросе исключения локальные переменные удаляется, никаких утечек.

`throw` в `read_vector` ––> перебрасывается в `solve`, там никак не обработать ––> летит дальше и ловится в `main`.

То есть не проверяя ошибку в solve, мы вытащили ошибку наверх. Собственно, для этого и нужны исключения – вытащить
ошибку с более глубоких уровней так, чтобы она не затронула промежуточные.

```c++
struct invalid_vector_format {};

std::vector<int> read_vector() {
    int n;
    if (!(std::cin >> n)) {
        throw invalid_vector_format();
    }
    std::vector<int> result(n);
    for (int i = 0; i < n; i++) {
        if (!(std::cin >> result[i])) {
            throw invalid_vector_format();
        }
    }
    return result;
}

void write_answer(const std::vector<int> &vec) {
    for (std::size_t i = 0; i < vec.size(); i++) {
        if (i) std::cout << " ";
        std::cout << vec[i];
    }
    std::cout << "\n";
}

void solve() {
    std::vector<int> a = read_vector();  // if exception is thrown, it's propagated
    std::vector<int> b = read_vector();  // if exception is thrown, it's propagated; local variables are cleaned up (stack unwind, раскрутка стека).
    
    // Тут какие-то вычисления
    std::vector<int> answer = a;
    answer.insert(answer.end(), b.begin(), b.end());
    
    write_answer(answer);
}
```

При этом наше сообщение об ошибки не очень: как именно вектор invalid format? Какой вектор сломался? A или B?

Можно добавить еще один параметр, имя вектора, но это усложение кода для обработки ошибок.

### Про утечки и деструкторы

Локальные переменные при возникновении ошибки уничтожаться, деструктор вызовется при любом завершении функции/скобок
(ошибка или удачное завершение). Все будет хорошо, никаких утечек. Называется _stack unwind_ (раскрутка стека).

`catch(...)` – поймай любое исключение.

```c++
struct err1 {};
struct err2 {};

struct with_destructor {
    int key;
    with_destructor(int key_) : key(key_) {}
    ~with_destructor() {
        std::cerr << "Destructed " << key << "\n";
    }
};

void bar() {
    with_destructor wd31(31);  // Implementation-defined stack unwind.
    try {
        with_destructor wd40(40);
        std::cerr << "3\n";
        throw err1();
        std::cerr << "x3\n";
    } catch (const err1 &e) {
        std::cerr << "4\n";
        throw err2();
        std::cerr << "x4\n";
    }
    std::cerr << "bar end\n";
}

void foo() {
    with_destructor wd20(20);  // Implementation-defined stack unwind.
    try {
        with_destructor wd30(30);  // Implementation-defined stack unwind.
        std::cerr << "2\n";
        bar();
        std::cerr << "x2\n";
    } catch (const err1 &e) {
        std::cerr << "z\n";
    }
    std::cerr << "foo end\n";
}

int main() {
    std::cerr << "1\n";
    {
        with_destructor wd10(10);
    }
    try {
        foo();
    } catch (...) {
        std::cerr << "caught!\n";
    }
std::cerr << "main end\n";
}
```

### Несколько catch

Можно писать несколько `catch`. При этом UB и `assert` не поймаются.

```c++
try {
    // throw err1();
    // throw err2();
    std::vector<int> vec(-1);
} catch (const err1 &) {
    std::cout << "1\n";
} catch (const err2 &) {
    std::cout << "2\n";
} catch (...) {  // Exceptions only. Not UB, not assertions!
    std::cout << "3\n";
}
```

### Наследование исключений

Можно сделать базовый класс и несколько наследников. Тогда можно будет ловить исключения по ссылке на базовый класс.

Если в первом `try`-`catch` ловить ошибку по значению, то произойдет слайсинг и поймается `Base`, а не `Derived` (грубо
говоря, Derived обрежется до Base).

При этом если структуру `Magic` можно преобразовать к `const Base&`, то при выкидывании исключения такого типа во втором
блоке оно не поймается – такие исключения работают только с наследованием, а не с преобразованиями.

Благодаря этому можно делать целую иерархию ошибок.

```c++
struct Base {
    virtual const char *who() const {
        return "Base";
    }
};

struct Derived : Base {
    const char *who() const override {
        return "Derived";
    }
};

struct Magic {
    operator Base() { return {}; }
};

int main() {
    try {
        throw Derived();
    } catch (const Base &e) {
    //    } catch (Base e) {
    std::cout << "Caught: " << e.who() << "\n";
}

    try {
        [[maybe_unused]] const Base &b = Magic();
        throw Magic();
    } catch (const Base &e) {  // Does not work, needs ~type match or inheritance.
        std::cout << "Caught Base\n";
    }
}
```

### Вложение try-блоки

Осторожно - `catch` относится к своему блоку `try`, а не к ближайшему сверху `try`! Можно перебрасывать наверх, если
нужно.

```c++
struct err1 {};
struct err2 {};

void bar() {
    try {
        try {
            std::cerr << "3\n";
            throw err1();
            std::cerr << "x3\n";
        } catch (const err1 &e) {
            std::cerr << "4\n";
            throw err2();
            std::cerr << "x4\n";
        } catch (const err2 &e) {
            std::cerr << "x5\n";
        }
    } catch (int e) {
        std::cerr << "caught int???\n";
    } catch (const err2 &e) {
        std::cerr << "caught err2!\n";
        throw e;
    }
    std::cerr << "bar end\n";
}

void foo() {
    try {
        try {
            std::cerr << "2\n";
            bar();  // std::cerr << "3\n4\n"; throw err2();
            std::cerr << "x2\n";
        } catch (const err1 &e) {
            std::cerr << "z\n";
        }
        std::cerr << "x21\n";
    } catch (int e) {
        std::cerr << "x22\n";
    }
    std::cerr << "foo end\n";
}

int main() {
    try {
        std::cerr << "1\n";
        foo();
        std::cerr << "xxx\n";
    } catch (const err2 &) {
        std::cerr << "5\n";
    }
    std::cerr << "main continues\n";
}
```

### Непойманное исключение

_Implementation-defined stack unwind_ – если исключение не поймано, то зависит от компилятора. Он может раскрутить стек,
а может и не раскручивать. Может уронить программу и не вызвать деструкторы.

```c++
struct err1 {};
struct err2 {};

struct with_destructor {
    int key;
    with_destructor(int key_) : key(key_) {}
    ~with_destructor() {
        std::cout << "Destructed " << key << "\n";
    }
};

void bar() {
    with_destructor wd31(31);  // Implementation-defined stack unwind.
    try {
        with_destructor wd40(40);
        std::cout << "3\n";
        throw err1();
        std::cout << "x3\n";
    } catch (const err1 &e) {
        std::cout << "4\n";
        throw err2();
        std::cout << "x4\n";
    }
    std::cout << "bar end\n";
}

void foo() {
    with_destructor wd20(20);  // Implementation-defined stack unwind.
    try {
        with_destructor wd30(30);  // Implementation-defined stack unwind.
        std::cout << "2\n";
        bar();
        std::cout << "x2\n";
    } catch (const err1 &e) {
        std::cout << "z\n";
    }
    std::cout << "foo end\n";
}

int main() {
    std::cout << "1\n";
    {
        with_destructor wd10(10);
    }
    try {
        foo();
    } catch (...) {
//        throw;
    }
    std::cout << "main end\n";
}
```

### Исключения стандартной библиотеки

В STL есть целая иерархия исключений: `std::runtime_error`, `std::logic_error` или не относятся ни к чему. В свою
очередь они наследуются от некоторого базового типа `std::exception`, у которого есть метод what, содержащий информацию
об ошибке.

```c++
#include <boost/core/demangle.hpp>
#include <exception>
#include <iostream>
#include <vector>
#include <string>

struct Base { virtual ~Base() = default; };
struct Derived1 : Base {};
struct Derived2 : Base {};

int main() {
    try {
        // Some are std::runtime_error, some are std::logic_error, some are neither.
        // std::vector<int> vec(-1);  // std::bad_alloc
        /*{
            Derived1 d1;
            Base &b = d1;
            [[maybe_unused]] Derived2 *d2a = dynamic_cast<Derived2*>(&b);  // nullptr
            std::cout << d2a << "\n";
            [[maybe_unused]] Derived2 &d2b = dynamic_cast<Derived2&>(b);  // std::bad_cast
        }*/
        // std::cout << std::stoi("123") << "\n";
        // std::cout << std::stoi("foo") << "\n";  // std::invalid_argument
        // std::cout << std::stoi("123foo") << "\n";  // no exceptions, ok
        // std::cout << std::vector<int>(10).at(15) << "\n";  // std::out_of_range
        // See Boost::Dll example with 'file not found'
    } catch (const std::exception &e) {
        std::cout << "Error type=" << boost::core::demangle(typeid(e).name()) << " what()=" << e.what() << "\n";
    }
}
```

### Наследование от `std::exception`

Свои исключения можно наследовать от стандартных. Можно напрямую от `std::exception`. Но лучше наследоваться от
'std::runtime_error' или `std::logic_error` (в отличие от `std::exception` у них есть конструктор не от `char*`, а
от `std::string`).

Потом можно будет ловить по ссылке на `std::exception`.

```c++
struct my_exception : std::exception {
    const char *what() const noexcept override {
        return "my_exception";
    }
};

struct my_runtime_error : std::runtime_error {  // Choice between runtime_error and logic_error is not strict.
    my_runtime_error() : std::runtime_error("yay! " + std::to_string(123)) {}
};

int main() {
    try {
        throw my_exception();
    } catch (const std::exception &e) {
        std::cout << e.what() << "\n";
    }

    try {
        throw my_runtime_error();
    } catch (const std::exception &e) {
        std::cout << e.what() << "\n";
    }

    try {
        throw my_runtime_error();
    } catch (const std::runtime_error &e) {
        std::cout << e.what() << "\n";
    }
}
```

### Summary

Лучше не использовать слепо исключения, а подумать об обработке ошибок. Использовать исключения рекомендуется только
если это проще, чем написание кодов ошибок. Особенно не стоит использовать исключения для обработка ошибок
программирования, всегда можно заменить их кодами ошибок (а в обратную сторону уже труднее). И, конечно, исключения
должны быть частью контракта.