## lecture 17, _13-02-23_

---

## Про классы

### public, private, protected inheritance

Также, как и с полями – `private`, `protected` и `public`. Для классов наследование по умолчанию `private`,
у структур – `public`. Влияет на то, кто понимает, что класс отнаследован от базового класса.

```cpp
struct Base {
    void foo() {
    }
};

struct Derived1 : public Base {};  // Default for 'struct', the most popular.
struct Derived2 : protected Base {};
struct Derived3 : private Base {  // Default for 'class'.
    void baz() {
        foo();
        Derived3 d3;
        [[maybe_unused]] const Base &b = d3;
    }
};
struct Derived22 : /* public */ Derived2 {
    void bar() {
        foo();
        Derived2 d2;
        [[maybe_unused]] const Base &b2 = d2;
    }
};

struct Derived33 : /* public */ Derived3 {
    void bar() {
    // foo();
    [[maybe_unused]] ::Base b;  // :: is important
    // [[maybe_unused]] const ::Base &b2 = *this;
    // [[maybe_unused]] const ::Base &b3 = static_cast<const ::Base &>(*this);
    [[maybe_unused]] const ::Base &b4 =
        (const ::Base
            &)*this;  // meh, C-style cast ignores access modifiers
    }
};
```

`private` – Derived3 знает, что он отнаследован от Base.

Derived33 не знает, что Derived3 наследован от Base --> нельзя вызывать методы Base, создавать поле
такого типа (лайфхак: ::Base сработает (не из-за наследования, а просто поле)), нельзя взять ссылку на себя как на Base.

`protected` – Derived2 знает, что он отнаследован от Base. Наследники не могут вызывать методы Base.

```c++
int main() {
    Base b;
    Derived1 d1;
    Derived2 d2;
    Derived3 d3;

    b.foo();
    d1.foo();
    // d2.foo();
    // d3.foo();

    [[maybe_unused]] const Base &b1 = d1;

    // [[maybe_unused]] const Base &b2x = d2;
    // [[maybe_unused]] const Base &b2y = static_cast<const Base &>(d2);
    [[maybe_unused]] const Base &b2z =
        (const Base &)d2;  // meh, C-style cast ignores access modifiers

    // [[maybe_unused]] const Base &b3x = d3;
    // [[maybe_unused]] const Base &b3y = static_cast<const Base &>(d3);
    [[maybe_unused]] const Base &b3z =
        (const Base &)d3;  // meh, C-style cast ignores access modifiers
}
```

! важно помнить, что у классов наследование приватное по умолчанию.

### Пример приватного наследования

Из boost: чтобы запретить классу копироваться, можно отнаследоваться от класса `noncopyable`. При этом делаем приватное
наследование, чтобы запретить возможность кастоваться к `noncopyable`.

```c++
struct noncopyable {  // boost::noncopyable
    noncopyable() = default;
    noncopyable(const noncopyable &) = delete;
    noncopyable(noncopyable &&) = delete;
    noncopyable &operator=(const noncopyable &) = delete;
    noncopyable &operator=(noncopyable &&) = delete;
};

struct Foo : private noncopyable {};
struct Bar : private noncopyable {};
struct Baz : private noncopyable {};

int main() {
    Foo f;
    // noncopyable &n = f;  // WTF, 'private' prevents that.

    // Foo f2 = f;
}
```

### Slicing

Есть класс и есть наследник.

```c++
struct Base {
    int x = 10;
    void foo() const {
        std::cout << "x=" << x << "\n";
    }
};

struct Derived : Base {
    int y = 20;
    void bar() const {
        foo();
        std::cout << "y=" << y << "\n";
    }
};

void bar(Base b) {  // Slicing: we create a new object
    std::cout << "bar(" << b.x << ")\n";
    const Derived &d = static_cast<const Derived&>(b);  // derivedcast, UB
    std::cout << ".y=" << d.y << "\n";  // UB
    &d.y;  // UB
}
```

Вызываем функцию, принимающую по значению, а не по ссылке. Тогда из Derived создастся объект типа Base и при попытке
сделать derived_cast возникнет UB.

```c++
{
    Derived d;
    d.x = 123;
    // Base(const Base &other) : x(other.x)
    bar(d);  // Always UB.
}
{
    Base b;
    bar(b);  // Always UB.
}
```

### Защита от slicing'а

Запретить в базовом классе копирование и перемещение. Тогда код не сломается (чаще всего), а при попытке принять Derived
по значению
будет ошибка компиляции (нет копирования).

```c++
struct Base {
    int x = 10;
    void foo() const {
        std::cout << "x=" << x << "\n";
    }

    Base() {}
    Base(const Base &) = delete;
    Base(Base &&) = delete;
    Base &operator=(const Base &) = delete;
    Base &operator=(Base &&) = delete;
};
```

### Делегирующий конструктор

Конструктор вызывает собственный конструктор типа, а потом может еще что-то доделать, если надо.

```c++
bigint(const std::string &s) {
    // TODO: ...
    std::cout << "constructing from string " << s << "\n";
}
bigint(int x) : bigint(std::to_string(x)) {  // Delegating constructor
    // bigint(std::to_string(x));  // bad attempt :(
    std::cout << "constructing from int " << x << "\n";
}
bigint() : bigint(0) {}
```

## Странный синтаксис исключения

### rethrow

Модификация 1: наследуемся от , чтобы лучше работать со страндартными библиотеками + была бы возможность ловить в main
какой-то exception.

```c++
struct invalid_vector_format : std::runtime_error {
    invalid_vector_format() : std::runtime_error("Invalid vector format") {}
};

...

int main() {
    try {
        solve();
    } catch (const std::exception &err) {  // !!! Modification 4
        std::cout << err.what() << "\n";
    }
}
```

Модификация 2: сначала ловим ошибку внутри функции, а потом перебрасываем, чтобы она поймалась в main.

`throw e` – перебрасываем пойманное исключение, если знаем его тип.
`throw` – смотрит, какое исключение поймано, и выбрасывает ровно его. Можно писать не только в catch.

```c++
void rethrow() {
    std::cout << "Rethrowing...\n";
    throw;
}

void solve() {
    std::vector<int> a;
    try {
    a    = read_vector();
    } catch (const invalid_vector_format &e) {
        std::cout << "Caught error while reading vector a, propagating...\n";
        // throw e;  // rethrow exception 'e', but what about other types?
        // throw;  // does the same
        rethrow();  // does the same, but indirectly
    }
    ...
}
```

Модификация 3: `catch(...)` – поймать что-нибудь.

```c++
void solve() {
    ...
    std::vector<int> b;
    try {
        b = read_vector();  
    } catch (...) {
        std::cout << "Caught error while reading vector b, propagating...\n";
        throw;  // works with `...`
    }
        ...
    }
    std::vector<int> answer = a;
    answer.insert(answer.end(), b.begin(), b.end());

    write_answer(answer);
}
```

### throw slicing

`throw a;` – произойдет slicing (так как прилетает исключение по значению), тип выброшенного исключения
будет `std::exception`.
`throw;` – так не потеряется тип сключения, лучше использовать, чтобы не терять динамический тип сключения.

```c++
#include <exception>
#include <iostream>
#include <stdexcept>

void foo() {
    try {
        throw std::runtime_error("Hello World");
    } catch (std::exception &a) {
        // throw a;  // oops, slicing
        throw;  // no slicing
    }
}
int main() {
    try {
        foo();
    } catch (std::exception &e) {
        std::cout << "caught in main(): " << e.what() << "\n";
    }
}
```

## Intermediate exceptions

### Когда могут возникать исключения

Исключения вылетают только если их кто-то явно бросил (например, bad_alloc при нехватке памяти), при этом UB – это не
исключение.
То есть в С++ исключения обрабатывает не все ошибки, а только те, о которых договорились.

```c++
int main() {
    int x = 2 * 2'000'000'000;  // UB
    int y = 2 / 0;  // UB
    assert(false);  // assertion failed, может быть удалён.

    std::vector<int> vec(10);  // Может быть std::bad_alloc, если памяти не хватило.
    vec[10] = 5;  // UB
    vec.at(10) = 5;  // std::out_of_bounds : std::exception, гарантируется.
}
```

### Гарантии икслючений (exception safety)

Пусть у нас есть такая функция, выкидывающая bad_alloc.

```c++
void do_something() {
    throw std::bad_alloc();  // Uncomment when running under Valgrind/ASan, it does not like not having enough memory and will close instead of bad_alloc.
    std::vector<int> vec(100'000'000'000);
    vec[vec.size() - 1] = 123;
}
```

Без гарантий: выделили data, при выбросе исключения будет утечка (не почистили data).

```c++
void no_guarantee() {
    std::cout << "2+2=";
    int *data = new int[10];
    do_something();
    delete[] data;
    std::cout << "4\n";
}
```

Базовая гарантия: если исключение произошло, то хотя бы нет UB и утечек памяти.

```c++
// Basic exception safety: no leaks, no UB
void basic_guarantee_1() {
std::cout << "2+2=\n";
std::vector<int> data(10);
do_something();
std::cout << "4\n";
}

void basic_guarantee_2() {
std::cout << "2+2=4\n";
std::vector<int> data(10);
do_something();
}
```

Строгая (сильная) гарантия исключения или семантика отката назад: если произошло исключение, то в мире ничего не
поменялось
(или функция выполнилась полностью успешно, или выбросилось исключение и в мире ничего не поменялось (например, вывелось
2+2=4 полностью, но тут
тоже зависит от нашей интерпретации того, что значит, что ничего не поменялось))

```c++
// Strong exception safety (rollback semantics): nothing unchanged
void strong_guarantee() {
std::vector<int> data(10);
do_something();
// What is "nothing"? Can we output?
std::cout << "2+2=4\n";
}
```

Нет исключений: следовательно, самая строгая гарантия – вообще без исключений)))

```c++
void noexcept_guarantee() {
    assert(std::cout.exceptions() == std::ios_base::goodbit);
    std::cout << "2+2=4\n";
}
```

### noexcept

`noexcept` функция не должна выкидывать исключений, а если и выкидывает, то вызовется `std::terminate` и убьет
программу.
При этом никаких деструктором не вызывается.

```c++
void check_n(int n) {
    if (n < 0) {
        throw 0;
    }
}

void foo() noexcept {  // If exception: std::terminate(), no dtor calls
    std::cout << "foo() start\n";
    int n;
    std::cin >> n;
    check_n(n);
    std::cout << "foo() end\n";
}
```

При этом можно ловить и выкидывать исключения внутри, главное, чтобы наружу не вылетело ничего.

```c++
void check_n(int n) {
    if (n < 0) {
        throw 0;
    }
}

void foo() noexcept {  // If exception: std::terminate(), no dtor calls
    std::cout << "foo() start\n";
    int n;
    std::cin >> n;
    try {
        check_n(n);
    } catch (...) {
        std::cout << "Caught inside\n";
    }
    std::cout << "foo() end\n";
}
```

### Пример функции, помеченной noexcept почти всегда

Деструктор может вызываться в процессе обработки исключений. Поэтому если, например, в деструкторе вызвалось 100
исключений, то
С++ просто уронит программу.

Поэтому с С++11 почти всегда неявно дописывается `noexcept`.

```c++
#include <iostream>

void maybe_throw() {
    static int remaining = 2;
    if (!--remaining) { 
        throw 0;
    }
}

struct Foo {
    Foo() {
        std::cout << "Foo() " << this << "\n";
    }
    ~Foo() {
        std::cout << "~Foo() " << this << "\n";
    maybe_throw();
}
};

int main() {
    try {
        try {
            Foo a;
            Foo b;
            Foo c;
            std::cout << "before throw\n";
            // TODO: split in C++03 and C++11
            throw 1;
            std::cout << "after throw\n";
        } catch (int x) {
            std::cout << "caught " << x << "\n";
        } catch (...) {
            std::cout << "caught something\n";
        }
    } catch (...) {
        std::cout << "caught outside\n";
    }
    // C++03: two exceptions simultanously => std::terminate().
// C++11: dtors are noexcept, always std::terminate().
}
```

### Плюсы и минусы noexcept

Pros:

1) noexcept in function signature: better documentation
2) noexcept in function signature: can be checked in compile-time and adjusted for (e.g. algorithmically)
3) May be (or not) be faster: https://stackoverflow.com/questions/16104057/does-noexcept-improve-performance

Cons:

1) noexcept in function signature: compiler does not force anything, but happily terminates the program
2) Impossible to do "negative testing" that the function catches errors as
   expected: https://bloomberg.github.io/bde-resources/doxygen/bde_api_prod/group__bsls__asserttest.html#4.1

What we do in this course for training:

1) Specify noexcept everywhere where there are no exceptions including bad_alloc.
2) Strive for more noexcept.

### noexcept в структурах

Инициализация по умолчанию `noexcept` (нет никаких операций).

Инициализация с оператором `new` не `noexcept` (может быть `std::bad_alloc`).

Копирование не `noexcept` (может быть сложная логика с вызовом оператора `new`).

Перемещение почти всегда `noexcept` (почти всегда это просто возня с указателями; обычно если он может быть не noexcept,
то скорее
всего вы делаете что-то не так).

Оператор присваивания копирующий не `noexcept` (может быть с копированием памяти).

Оператор присваивания перемещающий `noexcept` (внутри может быть вызов деструктора, но он noexcept, так что все ок).

Деструктор `noexcept` неявно, так что не помечаем.

```c++
// move constructor/assignment operator can (and should) almost always be noexcept
struct IntWrapper {
int *data;

IntWrapper() noexcept : data(nullptr) {
}

IntWrapper(int x) : data(new int(x)) {
}

IntWrapper(const IntWrapper &other) : data(other.data ? new int(*other.data) : nullptr) {
}

IntWrapper(IntWrapper &&other) noexcept : data(other.data) {
    other.data = nullptr;
}

IntWrapper& operator=(const IntWrapper &) {
    return *this;
}

IntWrapper& operator=(IntWrapper &&other) noexcept {
   if (!other.data) {
      delete data;  // noexcept
      data = nullptr;
   } else {
      if (data) {
        *data = *other.data;
      } else {
         data = other.data;
         other.data = nullptr;
      }
   }
   return *this;
}

~IntWrapper() {
   delete data;
   }
};
```

### RAII

Resource Acquisition Is Initialization. Захват ресурса есть инициализация.

1) При захвате ресурсов конструктор должен устанавливать инвариант. При невозможности – выбрасывать исключение.
2) Деструктор должен освобождать все ресурсы.

RAII – свойство некоторого класса. Иногда говорят: в коде используются RAII-классы.

```c++
int main() {
    // RAII: Resource Acquisition Is Initialization
    {
        std::vector<int> v(1'000'000);
        // Invariant: v.size() == 1'000'000, memory allocation succeeded.
        v[999'999] = 123;
        // RAII part 1: constructor has to establish invariant and grab resources. Throw an exception if that's impossible. No exit codes.
    }  // RAII part 2: destructor has to free all resource.

    try {
        std::vector<int> v(100'000'000'000);
        // Invariant: memory allocation succeeded.
        v[99'999'999'999] = 123;
    } catch (std::bad_alloc &) {
        // Impossible to access 'v' with incorrect invariant!
        std::cout << "caught bad_alloc\n";
    }
    // Jargon: 'RAII' may only mean part 2: destructor cleans up everything.
    // Constructing object is less strict, see ifstream.
}
```

### Исключения в конструкторе

Нельзя поймать ошибки только в конструкторе.
(можно сделать вектор пустым, а потом resize (то есть разделить ), но это не RAII-чно)

```c++
void may_throw(std::vector<int> &) {
    // maybe throw exception
}

int main() {
    try {
        // try {
        std::vector<int> v(100'000'000'000);
        // } catch
        v[99'999'999'999] = 123;
        may_throw(v);
    } catch (std::bad_alloc &) {
        std::cout << "caught bad_alloc inside v ctor or from may_throw\n";
    }
}
```

Не очень красиво, но:

```c++
int main() {
    try {
        // try {
        std::vector<int> v(100'000'000'000);
        // } catch
        v[99'999'999'999] = 123;
        may_throw(v);
    } catch (std::bad_alloc &) {
        std::cout << "caught bad_alloc inside v ctor or from may_throw\n";
    }
}
```

### Исключения в разных единицах трансляции

В рамках одной программы все более менее хорошо, внутри библиотек – спорно.

```c++
// a.cpp
#include
<exception>
#include
<iostream>

void foo();

int main() {
try {
foo();
} catch (std::exception &e) {
std::cout << "Exception: " << e.what() << "\n";
}
}

// b.cpp
#include
<iostream>

void bar(int i);

void foo() {
for (int i = 0; i < 5; i++) {
std::cout << "i=" << i << "\n";
bar(i);
}
}

// c.cpp
#include
<exception>

struct my_error : std::exception {
const char *what() const noexcept override {
return "my_error";
}
};

void bar(int i) {
if (i == 3) {
th  row my_error();
}
}
```

### Скорость исключений

Теоретически компилятор мог бы оптимизировать функции, зная, что исключения не кидаются.

```c++
#include <chrono>
#include <iostream>

// There was no difference with/without noexcept with this example, but it may happen:
// 1. Say hello to no-noexcept-move and strong exception safety (will be later).
// 2. One can optimize code like `i++; my_noexcept(); i++;`
// 3. There is no need to prepare for stack unwind.
//
// -fno-exceptions did not make a difference for me as well.

bool foobar(int a, int b, bool please_throw) noexcept {
    /* if (please_throw) {
        if (a % b) {
            throw 0;
        }
        return true;
    }*/
    return a % b == 0;
}

const int STEPS = 100'000'000;

int main() {
    auto start = std::chrono::steady_clock::now();
    
    for (int i = 0; i < STEPS; i++) {
        //        try {
        foobar(10, 3, false);
        //        } catch (...) {
        //        }
    }

auto duration = std::chrono::steady_clock::now() - start;
std::cout << std::chrono::duration_cast<std::chrono::milliseconds>(duration).count() << "ms\n";
}
```

Исключения тормозят программу примерно в 1000 раз больше, чем просто возврат из функции.

```c++
#include <chrono>
#include <iostream>

// Conclusion: exceptions are for exceptional cases only! Sad path is much, much slower.

bool foobar(int a, int b, bool please_throw) {
//    if (please_throw) {
        if (a % b) {
            //throw 0;  // todo: commenting out makes program faster
            return false;
        }
        return true;
//    }
    return a % b == 0;
}

const int STEPS = 100'000'000; // Note: much fewer steps.

int main() {
    auto start = std::chrono::steady_clock::now();

    for (int i = 0; i < STEPS; i++) {
//        try {
            foobar(12, 3, true);
//        } catch (...) {
//        }
    }

    auto duration = std::chrono::steady_clock::now() - start;
    std::cout << std::chrono::duration_cast<std::chrono::milliseconds>(duration).count() << "ms\n";
}
```

Мораль: исключения заоптимизированы так, что если вы их не кидаете, то вам почти бесплатно, а если кидаете, то обработка
занимает гораздо больше времени.

### Немного замечаний

Some projects disabled exceptions altogether due to:

1. Little to no support in a compiler
2. Slow happy path
3. Hard-to-maintain code

Example: Google.
Enabling exceptions back is hard due to the lack of exception safety. They did not.
Stereotype about hardware engineers: `-fno-exceptions`
---