## lecture 18, _20-02-23_

---

## Exceptions

### Exception ptr

Позволяет ловить исключения и запоминать их. Хранит не исключение, а указатель на него (аналогично
как shared ptr). Можно копировать. Если нет исключения, то ptr "нулевой".

```c++
struct my_exception {
    int value;
};

void foo(int x) {
    throw my_exception{x + 10};
}


int main() {
    std::exception_ptr err;  // shared_ptr<exception>
    // Can be created using std::make_exception_ptr or std::current_exception.
    auto save_exception = [&]() {
        // Can be called at any point in the programm, not necessarily right inside `catch`.
        // If there is no "current" exception, returns `exception_ptr{}`.
        err = std::current_exception();
    };
    
    try {
        std::cout << "before foo(1)\n";
        foo(1);
        std::cout << "after foo(1)\n";
    } catch (...) {
        std::cout << "saving exception...\n";
        save_exception();
        // Out-of-scope: one can build nested exceptions: https://en.cppreference.com/w/cpp/error/nested_exception
    }
}
```

Чтобы прочитать исключение, нужно его перебросить и поймать.

```c++
try {
    if (err) {
        // The only way to 'read' `exception_ptr`.
        std::rethrow_exception(err);  // Requires non-empty `err`.
    } else {
        std::cout << "no exception\n";
    }
} catch (my_exception &e) {
    std::cout << "e=" << e.value << "\n";
}
```

Зачем это нужно:

* Чтобы писать вложенные исключения (поймать, перебросить с большей информацией).
* Чтобы перебрасывать исключения между потоками.

### Исключения и (не)утечки памяти

Основное правило – если вылетело исключение, то утечек не ожидается. Как именно – читай дальше.

Будем рассматривать такой класс:

```c++
template<int X, bool SHOULD_THROW = false>
struct with_destructor {
    // If throws, object is dead, basic safety ~ strong safety.
    with_destructor(bool should_throw = false) {
        std::cout << "constructing " << X << " " << this << "\n";
        if (SHOULD_THROW || should_throw) {
            throw 0;
        }
    }
    ~with_destructor() {
        std::cout << "destructing " << X << " " << this << "\n";
    }
};
```

### Конструктор

**Один объект**

```c++
try {
    with_destructor<0> x;
    with_destructor<1> y(true);
//        with_destructor<1, true> y;
    with_destructor<2> z;
} catch (...) {
    std::cout << "Caught\n";
}
```

Предполагается, что если конструктор завершился, то объект создан, а если нет, то что будет?

Пусть исключение кидает конструктор. В этом случае...

...в С++ НЕ вызывается деструктор. По причине "конструктор может сломаться в разных местах" (непонятно, какие объекты
надо будет чистить, может быть проинициализировано их разное подмножество). Поэтому сказали, что конструктор сам должен
почистить за собой память, если вылетело исключение, он же знает, где упал и что успел до этого проинициализировать.

Про гарантию конструктора: обычно предоставляет базовую гарантию, про строгую – неясно, но
обычно да. Так что они идут вместе.

**Массив объектов**
По сути то же самое, что создать 4 отдельных объектов, разницы нет. Что для массива, что для вектора.

```c++
try {
    with_destructor<1> arr[]{false, false, true, false};
} catch (...) {
    std::cout << "Caught\n";
}

try {
    std::vector<with_destructor<1>> vec{false, false, true, false};
} catch (...) {
    std::cout << "Caught\n";
}
```

**Объекты класса**
Пусть исключение вылетает внутри какого-то поля класса. Поля инициализируются сверху-вниз. Вызовется деструктор только у
сконструированных a и b.

```c++
struct Foo {
    with_destructor<1> a;
    with_destructor<2> b;
    with_destructor<3, true> c;
    with_destructor<4> d;
};

int main() {
    try {
        with_destructor<0> x;
        Foo f;
    } catch (...) {
        std::cout << "Caught\n";
    }
}
```

**Member initialization list**

Теперь добавим member-initialization list. Все еще никаких утечек, удалим только a.

```c++
struct Foo {
    with_destructor<1> a;
    with_destructor<2> b;
    with_destructor<3, true> c;
    with_destructor<4> d;

    Foo() : a(), b(true), c(), d() {
        std::cout << "Foo()\n";
    }
    ~Foo() {
        std::cout << "~Foo()\n";
    }
};

int main() {
    try {
        with_destructor<0> x;
        Foo f;
    } catch (...) {
        std::cout << "Caught\n";
    }
}
```

**Конструктор**
А теперь все поля проинициализированы, но сам конструктор выкинул исключение. Так как у нас RAII классы, то все еще все
хорошо.

```c++
struct Foo {
    with_destructor<1> a;
    with_destructor<2> b;
    with_destructor<3> c;
    with_destructor<4> d;

    Foo() : a(), b(), c(), d() {
        std::cout << "Foo()\n";
        throw 0;
    }
    ~Foo() {
        std::cout << "~Foo()\n";
    }
};

int main() {
    try {
        with_destructor<0> x;
        Foo f;
    } catch (...) {
        std::cout << "Caught\n";
    }
}
```

### Наследование

**Базовый класс**
Инициализация упала в Base --> инициализация Derived даже не началась.

```c++
// Cases:
// 1. Base's member or constructor throws
// 2. Derived's member or constructor throws
struct Base {
with_destructor<1> a;
with_destructor<2, true> b;

Base() {
std::cout << "Base()\n";
}
~Base() {
std::cout << "~Base()\n";
}
};

struct Derived : Base {
with_destructor<3> c;
with_destructor<4> d;
Derived() /* : Base() */ {
std::cout << "Derived()\n";
}
~Derived() {
std::cout << "~Derived()\n";
}
};

int main() {
try {
with_destructor<0> x;
Derived d;
} catch (...) {
std::cout << "Caught\n";
}
}
```

**Наследник**
В таком случае воспринимаем базовый класс просто как поле, которое успешно проинициализировалось --> у него вызовется
деструктор.

```c++
struct Base {
    with_destructor<1> a;
    with_destructor<2> b;

    Base() {
        std::cout << "Base()\n";
    }
    ~Base() {
        std::cout << "~Base()\n";
    }
};

struct Derived : Base {
    with_destructor<3> c;
    with_destructor<4, true> d;
    Derived() /* : Base() */ {
        std::cout << "Derived()\n";
    }
    ~Derived() {
        std::cout << "~Derived()\n";
    }
};

int main() {
    try {
        with_destructor<0> x;
        Derived d;
    } catch (...) {
        std::cout << "Caught\n";
    }
}
```

### Делегирующий конструктор

**Внутри**
Деструктор Foo() не вызовется, так как объект все еще считается не созданным до конца.

```c++
struct Foo {
    with_destructor<1> a;
    with_destructor<2> b;
    with_destructor<3> c;
    with_destructor<4> d;

    Foo() {
        std::cout << "Foo()\n";
        std::cout << "throwing\n";
        throw 0;
    }
    Foo(int) : Foo() {  // After a single ctor is completed, object is created.
        std::cout << "Foo(int)\n";
    }
    ~Foo() {
        std::cout << "~Foo()\n";
    }
};

int main() {
    try {
        with_destructor<0> x;
        Foo f(10);
    } catch (...) {
        std::cout << "Caught\n";
    }
}
```

**Снаружи**
Компилятор считает, что после завершения первого конструктора объект создан, остальные конструкторы инварианты нарушить
уже не могут, поэтому деструктор вызовется,

```c++
struct Foo {
    with_destructor<1> a;
    with_destructor<2> b;
    with_destructor<3> c;
    with_destructor<4> d;

    Foo() {
        std::cout << "Foo()\n";
    }
    Foo(int) : Foo() {  // After a single ctor is completed, object is created.
        std::cout << "Foo(int)\n";
        std::cout << "throwing\n";
        throw 0;
    }
    ~Foo() {
        std::cout << "~Foo()\n";
    }
};

int main() {
    try {
        with_destructor<0> x;
        Foo f(10);
    } catch (...) {
        std::cout << "Caught\n";
    }
}
```

### Функции

**Параметры**

То же самое правило – деструктор вызовется только у a, функция не выполнится.

```c++
int remaining = 2;

struct Foo {
    Foo() {
        std::cout << "Foo() " << this << "\n";
    }
    Foo(const Foo &) {
        std::cout << "Foo(const Foo&) " << this << "\n";
        if (!--remaining) {
            throw 0;
        }
    }
    Foo &operator=(const Foo&) = delete;
    ~Foo() {
        std::cout << "~Foo " << this << "\n";
    }
};

void func(Foo, Foo, Foo) {
    std::cout << "func\n";
}

int main() {
    Foo a, b, c;
    try {
        std::cout << "before foo\n";
        func(a, b, c);
        std::cout << "after foo\n";
    } catch (...) {
        std::cout << "exception\n";
    }
}
```

**Interleaving**

У функции три параметра, вычисляются справа-налево или слева-направо (не гарантируется, как конкретно это будет). В
среднем вылетает исключение. Вызовется деструктор только у одного из них. Никаких утечек.

```c++
template<typename T1, typename T2, typename T3>
void foo(
    [[maybe_unused]] std::unique_ptr<T1> a,
    [[maybe_unused]] std::unique_ptr<T2> b,
    [[maybe_unused]] std::unique_ptr<T3> с
) {
    std::cout << "foo\n";
}

int main() {
     try {
         // OK only at and after C++17:
         foo(
             std::unique_ptr<with_destructor<1>>(new with_destructor<1>(false)),
             std::unique_ptr<with_destructor<2>>(new with_destructor<2>(true)),
             std::unique_ptr<with_destructor<3>>(new with_destructor<3>(false))
         );
     } catch (...) {
         std::cout << "caught\n";
     }
}
```

А до C++17 были утечки. И чтобы этого избежать надо бы использовать `make_unique` (нельзя разделить new и
конструирование на две части, как это мог сделать компилятор, но внутри функции так сделать уже нельзя).

```c++
/*
    // Before C++17:
    1. new with_destructor<3>(false)
    2. new with_destructor<2>(true)
    3. new with_destructor<1>(false)
    4. unique_ptr(....)
    5. unique_ptr(....)
    6. unique_ptr(....)
    // Before C++17:
    1. make_unique<with_destructor<3>>(false)
    2. make_unique<with_destructor<2>>(true)
    3. make_unique<with_destructor<1>>(false)
    
    // https://herbsutter.com/gotw/_102/
*/
```

**Возвращаемое значение-1**

Поймали исключение внутри return (так как происходит копирование), можно поймать.

```c++
int remaining = 1;

struct Foo {
    Foo() {
        std::cout << "Foo() " << this << "\n";
    }
    Foo(const Foo &) {
        std::cout << "Foo(const Foo&) " << this << "\n";
        if (!--remaining) {
            throw 0;
        }
    }
    Foo &operator=(const Foo&) = delete;
    ~Foo() {
        std::cout << "~Foo " << this << "\n";
    }
};

Foo func(int x) {
    Foo a, b;
    // We need some convoluted code so the compiler cannot use RVO/NRVO (optimizations).
    if (x == 0) {
        try {
            return a;
        } catch (...) {
            std::cout << "exception in func\n";
            return Foo();
        }
    } else {
        return b;
    }
}

int main() {
    Foo f = func(0);
    std::cout << "&f=" << &f << "\n";
}
```

**Возвращаемое значение-2**

А теперь у нас происходит не конструирование нового объекта возвращаемым значением, а копирование возвращаемого значения
в уже созданную переменную. Тогда исключение вылетит уже снаружи функции.

```c++
int remaining = 2;

Foo func([[maybe_unused]] int x) {
    Foo a, b;
    // We need some convoluted code so the compiler cannot use RVO/NRVO (optimizations).
    if (x == 0) {
        try {
            return a;
        } catch (...) {
            std::cout << "exception in func\n";
            return Foo();
        }
    } else {
        return b;
    }
}

int main() {
    Foo f;
    try {
        std::cout << "&f=" << &f << "\n";
        f = func(0);
        std::cout << "after f\n";
    } catch (...) {
        std::cout << "exception in main\n";
    }
}
```

### Особенность стека

Метод pop удаляет элемент, но не возвращает его. Ответ – чертовы исключения.

Пусть мы написали 'нормальный' стек, возвращающий в pop значение. Попытаемся присвоить это значение куда-то. Теперь если
при операторе = вылетает исключение, то происходит странное – стек уменьшился, но значение пропало.

```c++
template<typename T>
struct stack {
    std::vector<T> data;

    T pop() {
        T result = std::move(data.back());
        data.pop_back();
        return result;
    }
};

int main() {
    stack<int> s;
    s.data = std::vector{1, 2, 3, 4, 5};

    int x = 10;
    x = s.pop();  // If exception is thrown by `operator=`, `s` cannot restore stack state.
                  // Looks like strong guarantee violation.
}
```

Поэтому можно или не возвращать значение с помощью pop (тогда пользователю придется обращаться к вершине стека и
получать ссылку на элемент), или вот так.

```c++
template<typename T>
struct stack {
    std::vector<T> data;

    void pop_into(T &result) {
        result = std::move(data.back());
        data.pop_back();
    }
};

int main() {
    stack<int> s;
    s.data = std::vector{1, 2, 3, 4, 5};

    int x = 10;
    s.pop_into(x);  // All exceptions are handled by `pop` itself.
}
```

### Function try-block

Можно ловить исключения, вылетающие из конструктора базового класса:

**Конструктор**

```c++
struct Foo : Base {
    std::vector<int> a, b;

    Foo(const std::vector<int> &a_, const std::vector<int> &b_)
    try
        : a(a_)
        , b(b_)
    {
        std::cout << "constructor called\n";
    } catch (const std::bad_alloc &) {
        // Catching exceptions from: member initialization list (even omittied), constructor's body.
        std::cout << "Allocation failed\n";
        // All fields and bases are already destroyed. The object may be destroyed as well (e.g. delegating ctor).
        // We do not know what exactly has failed.
        // No way to resurrect the object. `throw;` is added implicitly.
    } catch (int x) {
        std::cout << "Oops\n";
        // We can change the exception, though.
        throw 10;
    }
};
```

**Деструктор**
То же самое можно сделать с деструктором (только надо бы добавить `noexcept(false)`).

```c++
struct Base {
    ~Base() noexcept(false) {
        throw 0;
    }
};

struct Foo : Base {
    ~Foo() try {
        std::cout << "destructing Foo\n";
    } catch (...) {
        // Catching exceptions from: destructors of fields and bases.
        // All fields and bases are already destroyed.
        // We do not know what exactly has failed.

        std::cout << "destruction exception\n";
        // `throw;` is added implicitly, but if we `return`, the destructor is considered not throwing.
        return;
    }
};

int main() {
    try {
        Foo f;
    } catch (...) {
        std::cout << "exception\n";
    }
}
```

**Любая функция**
Можно такую штуку провернуть с любой функцией. Но проблема в том, что заворачивание всего тела функции в try-catch блок
дало бы тот же эффект, так что неясно, есть ли в такой конструкции смысл. То есть вообще ничего дополнительного не
ловится.

```c++
Foo func(Foo a, Foo, Foo) try {
    std::cout << "func\n";
    return a;
} catch (...) {
    // Does not catch exceptions on argument creation.
    // The rest can be caught with the usual `try`-`catch`,
    // including `return`. So: useless.
    std::cout << "exception in func!\n";
    // No implicit `throw;`, we `return` normally by default.
    throw;
}
```

### Нарушение базовой гарантии

В данном случае при неявно сгенерированном операторе = вылетит исключение, поэтому только одно поле скопируется.

```c++
int throw_after = 1;

struct VectorHolder {
    std::vector<int> data;
    VectorHolder(int n, int val) : data(n, val) {}

    VectorHolder &operator=(const VectorHolder &other) {
       if (--throw_after < 0) {
           throw 0;
       }
        data = other.data;
        return *this;
    }
};

struct Foo {
private:
    VectorHolder a;
    VectorHolder b;

public:
    Foo(int n) : a(n, 1), b(n, 2) {}
    void check() {
        assert(a.data.size() == b.data.size());
    }
    // Oops: implicitly generated operator= assigns fields one-by-one.
};

int main() {
    Foo x(10);
    Foo y(20);
    x.check();
    y.check();
    try {
        x = y;
        // x.a = y.a;
        // x.b = y.b;
    } catch (...) {
        std::cout << "caught\n";
    }
    x.check();  // invariant violated?
}
```

## Потоки

### promise и future

Задача: есть два потока consumer и producer (один что-то читает, а второй – обрабатывает или один генерирует ответы, а
второй – что-то выводит и так далее).

Как перекидывать между ними значения?

Стандартное решение – `std::promise<...>` (то, что будем передавать), `std::future<...>` (то, что получаем).

std::promise – некая очередь длины один, кладем туда ("обещаем") с помощью set_value().

std::future получает обещанное значение с помощью get().

Помогает, когда нужно передавать одно значение. Если больше, то скорее всего придется писать
свою многопоточную очередь.

```c++
#include <chrono>
#include <future>
#include <iostream>
#include <string>
#include <thread>

int main() {
    std::promise<std::string> input_promise;
    std::future<std::string> input_future = input_promise.get_future();

    std::thread producer([&]() {
        std::string input;
        std::cin >> input;
        input_promise.set_value(std::move(input));
        std::this_thread::sleep_for(std::chrono::milliseconds(100));
        std::cout << "producer after set_value-1\n";
        std::this_thread::sleep_for(std::chrono::milliseconds(1000));
        std::cout << "producer after set_value-2\n";
    });

    std::thread consumer([&]() {
        std::cout << "Consumer started\n";
        std::string input = input_future.get();
        std::cout << "Consumed!\n";
        std::this_thread::sleep_for(std::chrono::milliseconds(2000));
        std::cout << "Processed string: " << input << "\n";
    });

    consumer.join();
    producer.join();
}
```

По сути promise – это std::optional + std::mutex, get – взять mutex и вернуть значение. Но если значения нет,
то надо как-то уснуть, пока оно не появится. Но как..?

### conditional_variable

std::condition_variable – еще один примитив синхронизации. Должен быть жестко связан с каким-то mutex и
каким-то условием, то есть позволяет быть уверенным, что условие true.

wait(l) –> жди, пока кто-нибудь не скажет notify_one(). wait пишется в while (особенность языка, что позволяет
разбудить случайный поток).

```c++
#include <chrono>
#include <condition_variable>
#include <iostream>
#include <mutex>
#include <string>
#include <thread>

int main() {
    std::mutex m;
    std::string input;
    bool input_available = false;
    std::condition_variable cond;

    std::thread producer([&]() {
//        while (true) {
            std::cin >> input;
            std::unique_lock l(m);
            input_available = true;
            cond.notify_one();  // Разбудит один случайный поток. Важно, чтобы это было ему по делу.
//        }
    });

    std::thread consumer([&]() {
//        while (true) {
            std::unique_lock l(m);
            while (!input_available) {  // while, не if!
                cond.wait(l);
            }
            // Эквивалентная while конструкция, чтобы было сложнее набагать и были понятнее намерения.
            cond.wait(l, []() { return input_available; });  // "ждём выполнения предиката".
            std::string input_snapshot = input;
            input_available = false;
            l.unlock();

            std::this_thread::sleep_for(std::chrono::milliseconds(2000));
            std::cout << "Got string: " << input_snapshot << "\n";
//        }
    });

    consumer.join();
    producer.join();
}
```